{"name": "test_loginc", "status": "broken", "statusDetails": {"message": "FileNotFoundError: [Errno 2] No such file or directory: './picture/微信头像.jpg'", "trace": "self = <test_allureModle.Test_login object at 0x000001679D527610>\n\n    @allure.story(\"用户名错误，登录失败\")\n    # --allure-link-pattern=issue:https://blog.csdn.net/weixin_44275820/article/details/105169871/issue/{}\n    @allure.issue(\"10086\",\"这是一个bug，需要修复\")\n    @allure.severity(allure.severity_level.NORMAL)    #正常问题\n    def test_loginc(self):\n>       allure.attach.file(\"./picture/微信头像.jpg\",name=\"这是一个图片\",attachment_type=allure.attachment_type.JPG)    #添加图片\n\ntest_allureModle.py:25: \n_ _ _ _ _ _ _ _ _ _ _ _ _ _ _ _ _ _ _ _ _ _ _ _ _ _ _ _ _ _ _ _ _ _ _ _ _ _ _ _ _ _ _ _ _ _ _ _ _ _ _ _ _ _ _ _ _ _ _ _ _ _ _ _ _ _ _ _ _ _ _ _ _ _ _ _ _ _ _ _ _ _ _ _ _ _ _ _ _ _ _ _ _ _ _ _ _ _ _ _ _ _ _ _ _ _ _ _ _ _ _ _ _ _ _ _ _ \nvenv\\lib\\site-packages\\allure_commons\\_allure.py:182: in file\n    plugin_manager.hook.attach_file(source=source, name=name, attachment_type=attachment_type, extension=extension)\nvenv\\lib\\site-packages\\pluggy\\hooks.py:286: in __call__\n    return self._hookexec(self, self.get_hookimpls(), kwargs)\nvenv\\lib\\site-packages\\pluggy\\manager.py:93: in _hookexec\n    return self._inner_hookexec(hook, methods, kwargs)\nvenv\\lib\\site-packages\\pluggy\\manager.py:84: in <lambda>\n    self._inner_hookexec = lambda hook, methods, kwargs: hook.multicall(\nvenv\\lib\\site-packages\\allure_pytest\\listener.py:226: in attach_file\n    self.allure_logger.attach_file(uuid4(), source, name=name, attachment_type=attachment_type, extension=extension)\nvenv\\lib\\site-packages\\allure_commons\\reporter.py:114: in attach_file\n    plugin_manager.hook.report_attached_file(source=source, file_name=file_name)\nvenv\\lib\\site-packages\\pluggy\\hooks.py:286: in __call__\n    return self._hookexec(self, self.get_hookimpls(), kwargs)\nvenv\\lib\\site-packages\\pluggy\\manager.py:93: in _hookexec\n    return self._inner_hookexec(hook, methods, kwargs)\nvenv\\lib\\site-packages\\pluggy\\manager.py:84: in <lambda>\n    self._inner_hookexec = lambda hook, methods, kwargs: hook.multicall(\nvenv\\lib\\site-packages\\allure_commons\\logger.py:53: in report_attached_file\n    shutil.copy2(source, destination)\nE:\\Python3anzhuan\\lib\\shutil.py:426: in copy2\n    copyfile(src, dst, follow_symlinks=follow_symlinks)\n_ _ _ _ _ _ _ _ _ _ _ _ _ _ _ _ _ _ _ _ _ _ _ _ _ _ _ _ _ _ _ _ _ _ _ _ _ _ _ _ _ _ _ _ _ _ _ _ _ _ _ _ _ _ _ _ _ _ _ _ _ _ _ _ _ _ _ _ _ _ _ _ _ _ _ _ _ _ _ _ _ _ _ _ _ _ _ _ _ _ _ _ _ _ _ _ _ _ _ _ _ _ _ _ _ _ _ _ _ _ _ _ _ _ _ _ _ \n\nsrc = './picture/微信头像.jpg', dst = 'E:\\\\pychramProject\\\\report\\\\results002\\\\e587a484-6b66-4a19-98af-0388ac301a73-attachment.jpg'\n\n    def copyfile(src, dst, *, follow_symlinks=True):\n        \"\"\"Copy data from src to dst in the most efficient way possible.\n    \n        If follow_symlinks is not set and src is a symbolic link, a new\n        symlink will be created instead of copying the file it points to.\n    \n        \"\"\"\n        if _samefile(src, dst):\n            raise SameFileError(\"{!r} and {!r} are the same file\".format(src, dst))\n    \n        file_size = 0\n        for i, fn in enumerate([src, dst]):\n            try:\n                st = _stat(fn)\n            except OSError:\n                # File most likely does not exist\n                pass\n            else:\n                # XXX What about other special files? (sockets, devices...)\n                if stat.S_ISFIFO(st.st_mode):\n                    fn = fn.path if isinstance(fn, os.DirEntry) else fn\n                    raise SpecialFileError(\"`%s` is a named pipe\" % fn)\n                if _WINDOWS and i == 0:\n                    file_size = st.st_size\n    \n        if not follow_symlinks and _islink(src):\n            os.symlink(os.readlink(src), dst)\n        else:\n>           with open(src, 'rb') as fsrc, open(dst, 'wb') as fdst:\nE           FileNotFoundError: [Errno 2] No such file or directory: './picture/微信头像.jpg'\n\nE:\\Python3anzhuan\\lib\\shutil.py:259: FileNotFoundError"}, "attachments": [{"name": "这是一个图片", "source": "e587a484-6b66-4a19-98af-0388ac301a73-attachment.jpg", "type": "image/jpg"}], "start": 1622609171534, "stop": 1622609171535, "uuid": "0dec951e-d667-4b23-ada6-162b4a637ada", "historyId": "32dc2cf37dd620238550402dc4294a99", "testCaseId": "cc1930e72abd7cd6dd186d27231ce06d", "fullName": "test_allureModle.Test_login#test_loginc", "labels": [{"name": "story", "value": "用户名错误，登录失败"}, {"name": "severity", "value": "normal"}, {"name": "feature", "value": "这是登录模块测试用例"}, {"name": "suite", "value": "test_allureModle"}, {"name": "subSuite", "value": "Test_login"}, {"name": "host", "value": "WJYF2003-0261"}, {"name": "thread", "value": "20776-MainThread"}, {"name": "framework", "value": "pytest"}, {"name": "language", "value": "cpython3"}, {"name": "package", "value": "test_allureModle"}], "links": [{"type": "issue", "url": "10086", "name": "这是一个bug，需要修复"}]}